[2024-09-01T07:36:57.145+0000] {local_task_job_runner.py:123} INFO - ::group::Pre task execution logs
[2024-09-01T07:36:57.166+0000] {taskinstance.py:2603} INFO - Dependencies all met for dep_context=non-requeueable deps ti=<TaskInstance: nyc_airbnb_etl.test_data manual__2024-09-01T07:36:42+00:00 [queued]>
[2024-09-01T07:36:57.175+0000] {taskinstance.py:2603} INFO - Dependencies all met for dep_context=requeueable deps ti=<TaskInstance: nyc_airbnb_etl.test_data manual__2024-09-01T07:36:42+00:00 [queued]>
[2024-09-01T07:36:57.176+0000] {taskinstance.py:2856} INFO - Starting attempt 1 of 1
[2024-09-01T07:36:57.191+0000] {taskinstance.py:2879} INFO - Executing <Task(PostgresOperator): test_data> on 2024-09-01 07:36:42+00:00
[2024-09-01T07:36:57.201+0000] {warnings.py:112} WARNING - /home/***/.local/lib/python3.12/site-packages/***/task/task_runner/standard_task_runner.py:70: DeprecationWarning: This process (pid=94) is multi-threaded, use of fork() may lead to deadlocks in the child.
  pid = os.fork()

[2024-09-01T07:36:57.202+0000] {standard_task_runner.py:72} INFO - Started process 96 to run task
[2024-09-01T07:36:57.202+0000] {standard_task_runner.py:104} INFO - Running: ['***', 'tasks', 'run', 'nyc_airbnb_etl', 'test_data', 'manual__2024-09-01T07:36:42+00:00', '--job-id', '165', '--raw', '--subdir', 'DAGS_FOLDER/nyc_airbnb_etl.py', '--cfg-path', '/tmp/tmpt5unxamt']
[2024-09-01T07:36:57.204+0000] {standard_task_runner.py:105} INFO - Job 165: Subtask test_data
[2024-09-01T07:36:57.271+0000] {task_command.py:467} INFO - Running <TaskInstance: nyc_airbnb_etl.test_data manual__2024-09-01T07:36:42+00:00 [running]> on host 26d23410e980
[2024-09-01T07:36:57.413+0000] {taskinstance.py:3122} INFO - Exporting env vars: AIRFLOW_CTX_DAG_OWNER='***' AIRFLOW_CTX_DAG_ID='nyc_airbnb_etl' AIRFLOW_CTX_TASK_ID='test_data' AIRFLOW_CTX_EXECUTION_DATE='2024-09-01T07:36:42+00:00' AIRFLOW_CTX_TRY_NUMBER='1' AIRFLOW_CTX_DAG_RUN_ID='manual__2024-09-01T07:36:42+00:00'
[2024-09-01T07:36:57.415+0000] {logging_mixin.py:190} INFO - Task instance is in running state
[2024-09-01T07:36:57.416+0000] {logging_mixin.py:190} INFO -  Previous state of the Task instance: queued
[2024-09-01T07:36:57.416+0000] {logging_mixin.py:190} INFO - Current task name:test_data state:running start_date:2024-09-01 07:36:57.166786+00:00
[2024-09-01T07:36:57.417+0000] {logging_mixin.py:190} INFO - Dag name:nyc_airbnb_etl and current dag run status:running
[2024-09-01T07:36:57.418+0000] {taskinstance.py:731} INFO - ::endgroup::
[2024-09-01T07:36:57.418+0000] {sql.py:282} INFO - Executing: 
            SELECT * FROM information_schema.tables 
        
[2024-09-01T07:36:57.429+0000] {base.py:84} INFO - Retrieving connection 'test-connection'
[2024-09-01T07:36:57.448+0000] {base.py:84} INFO - Retrieving connection 'test-connection'
[2024-09-01T07:36:57.526+0000] {taskinstance.py:3301} ERROR - Task failed with exception
Traceback (most recent call last):
  File "/home/airflow/.local/lib/python3.12/site-packages/airflow/models/taskinstance.py", line 767, in _execute_task
    result = _execute_callable(context=context, **execute_callable_kwargs)
             ^^^^^^^^^^^^^^^^^^^^^^^^^^^^^^^^^^^^^^^^^^^^^^^^^^^^^^^^^^^^^
  File "/home/airflow/.local/lib/python3.12/site-packages/airflow/models/taskinstance.py", line 733, in _execute_callable
    return ExecutionCallableRunner(
           ^^^^^^^^^^^^^^^^^^^^^^^^
  File "/home/airflow/.local/lib/python3.12/site-packages/airflow/utils/operator_helpers.py", line 252, in run
    return self.func(*args, **kwargs)
           ^^^^^^^^^^^^^^^^^^^^^^^^^^
  File "/home/airflow/.local/lib/python3.12/site-packages/airflow/models/baseoperator.py", line 406, in wrapper
    return func(self, *args, **kwargs)
           ^^^^^^^^^^^^^^^^^^^^^^^^^^^
  File "/home/airflow/.local/lib/python3.12/site-packages/airflow/providers/common/sql/operators/sql.py", line 288, in execute
    output = hook.run(
             ^^^^^^^^^
  File "/home/airflow/.local/lib/python3.12/site-packages/airflow/providers/common/sql/hooks/sql.py", line 452, in run
    with self._create_autocommit_connection(autocommit) as conn:
  File "/usr/local/lib/python3.12/contextlib.py", line 137, in __enter__
    return next(self.gen)
           ^^^^^^^^^^^^^^
  File "/home/airflow/.local/lib/python3.12/site-packages/airflow/providers/common/sql/hooks/sql.py", line 574, in _create_autocommit_connection
    with closing(self.get_conn()) as conn:
                 ^^^^^^^^^^^^^^^
  File "/home/airflow/.local/lib/python3.12/site-packages/airflow/providers/postgres/hooks/postgres.py", line 176, in get_conn
    self.conn = psycopg2.connect(**conn_args)
                ^^^^^^^^^^^^^^^^^^^^^^^^^^^^^
  File "/home/airflow/.local/lib/python3.12/site-packages/psycopg2/__init__.py", line 122, in connect
    conn = _connect(dsn, connection_factory=connection_factory, **kwasync)
           ^^^^^^^^^^^^^^^^^^^^^^^^^^^^^^^^^^^^^^^^^^^^^^^^^^^^^^^^^^^^^^^
UnicodeDecodeError: 'utf-8' codec can't decode byte 0xd4 in position 83: invalid continuation byte
[2024-09-01T07:36:57.538+0000] {logging_mixin.py:190} INFO - Task instance in failure state
[2024-09-01T07:36:57.539+0000] {logging_mixin.py:190} INFO - Task start:2024-09-01 07:36:57.166786+00:00 end:2024-09-01 07:36:57.538125+00:00 duration:0.371339
[2024-09-01T07:36:57.539+0000] {logging_mixin.py:190} INFO - Task:<Task(PostgresOperator): test_data> dag:<DAG: nyc_airbnb_etl> dagrun:<DagRun nyc_airbnb_etl @ 2024-09-01 07:36:42+00:00: manual__2024-09-01T07:36:42+00:00, state:running, queued_at: 2024-09-01 07:36:44.598438+00:00. externally triggered: True>
[2024-09-01T07:36:57.540+0000] {logging_mixin.py:190} INFO - Failure caused by 'utf-8' codec can't decode byte 0xd4 in position 83: invalid continuation byte
[2024-09-01T07:36:57.540+0000] {taskinstance.py:1225} INFO - Marking task as FAILED. dag_id=nyc_airbnb_etl, task_id=test_data, run_id=manual__2024-09-01T07:36:42+00:00, execution_date=20240901T073642, start_date=20240901T073657, end_date=20240901T073657
[2024-09-01T07:36:57.553+0000] {taskinstance.py:340} INFO - ::group::Post task execution logs
[2024-09-01T07:36:57.554+0000] {standard_task_runner.py:124} ERROR - Failed to execute job 165 for task test_data ('utf-8' codec can't decode byte 0xd4 in position 83: invalid continuation byte; 96)
Traceback (most recent call last):
  File "/home/airflow/.local/lib/python3.12/site-packages/airflow/task/task_runner/standard_task_runner.py", line 117, in _start_by_fork
    ret = args.func(args, dag=self.dag)
          ^^^^^^^^^^^^^^^^^^^^^^^^^^^^^
  File "/home/airflow/.local/lib/python3.12/site-packages/airflow/cli/cli_config.py", line 49, in command
    return func(*args, **kwargs)
           ^^^^^^^^^^^^^^^^^^^^^
  File "/home/airflow/.local/lib/python3.12/site-packages/airflow/utils/cli.py", line 115, in wrapper
    return f(*args, **kwargs)
           ^^^^^^^^^^^^^^^^^^
  File "/home/airflow/.local/lib/python3.12/site-packages/airflow/cli/commands/task_command.py", line 483, in task_run
    task_return_code = _run_task_by_selected_method(args, _dag, ti)
                       ^^^^^^^^^^^^^^^^^^^^^^^^^^^^^^^^^^^^^^^^^^^^
  File "/home/airflow/.local/lib/python3.12/site-packages/airflow/cli/commands/task_command.py", line 256, in _run_task_by_selected_method
    return _run_raw_task(args, ti)
           ^^^^^^^^^^^^^^^^^^^^^^^
  File "/home/airflow/.local/lib/python3.12/site-packages/airflow/cli/commands/task_command.py", line 341, in _run_raw_task
    return ti._run_raw_task(
           ^^^^^^^^^^^^^^^^^
  File "/home/airflow/.local/lib/python3.12/site-packages/airflow/utils/session.py", line 97, in wrapper
    return func(*args, session=session, **kwargs)
           ^^^^^^^^^^^^^^^^^^^^^^^^^^^^^^^^^^^^^^
  File "/home/airflow/.local/lib/python3.12/site-packages/airflow/models/taskinstance.py", line 2995, in _run_raw_task
    return _run_raw_task(
           ^^^^^^^^^^^^^^
  File "/home/airflow/.local/lib/python3.12/site-packages/airflow/models/taskinstance.py", line 273, in _run_raw_task
    TaskInstance._execute_task_with_callbacks(
  File "/home/airflow/.local/lib/python3.12/site-packages/airflow/models/taskinstance.py", line 3149, in _execute_task_with_callbacks
    result = self._execute_task(context, task_orig)
             ^^^^^^^^^^^^^^^^^^^^^^^^^^^^^^^^^^^^^^
  File "/home/airflow/.local/lib/python3.12/site-packages/airflow/models/taskinstance.py", line 3173, in _execute_task
    return _execute_task(self, context, task_orig)
           ^^^^^^^^^^^^^^^^^^^^^^^^^^^^^^^^^^^^^^^
  File "/home/airflow/.local/lib/python3.12/site-packages/airflow/models/taskinstance.py", line 767, in _execute_task
    result = _execute_callable(context=context, **execute_callable_kwargs)
             ^^^^^^^^^^^^^^^^^^^^^^^^^^^^^^^^^^^^^^^^^^^^^^^^^^^^^^^^^^^^^
  File "/home/airflow/.local/lib/python3.12/site-packages/airflow/models/taskinstance.py", line 733, in _execute_callable
    return ExecutionCallableRunner(
           ^^^^^^^^^^^^^^^^^^^^^^^^
  File "/home/airflow/.local/lib/python3.12/site-packages/airflow/utils/operator_helpers.py", line 252, in run
    return self.func(*args, **kwargs)
           ^^^^^^^^^^^^^^^^^^^^^^^^^^
  File "/home/airflow/.local/lib/python3.12/site-packages/airflow/models/baseoperator.py", line 406, in wrapper
    return func(self, *args, **kwargs)
           ^^^^^^^^^^^^^^^^^^^^^^^^^^^
  File "/home/airflow/.local/lib/python3.12/site-packages/airflow/providers/common/sql/operators/sql.py", line 288, in execute
    output = hook.run(
             ^^^^^^^^^
  File "/home/airflow/.local/lib/python3.12/site-packages/airflow/providers/common/sql/hooks/sql.py", line 452, in run
    with self._create_autocommit_connection(autocommit) as conn:
  File "/usr/local/lib/python3.12/contextlib.py", line 137, in __enter__
    return next(self.gen)
           ^^^^^^^^^^^^^^
  File "/home/airflow/.local/lib/python3.12/site-packages/airflow/providers/common/sql/hooks/sql.py", line 574, in _create_autocommit_connection
    with closing(self.get_conn()) as conn:
                 ^^^^^^^^^^^^^^^
  File "/home/airflow/.local/lib/python3.12/site-packages/airflow/providers/postgres/hooks/postgres.py", line 176, in get_conn
    self.conn = psycopg2.connect(**conn_args)
                ^^^^^^^^^^^^^^^^^^^^^^^^^^^^^
  File "/home/airflow/.local/lib/python3.12/site-packages/psycopg2/__init__.py", line 122, in connect
    conn = _connect(dsn, connection_factory=connection_factory, **kwasync)
           ^^^^^^^^^^^^^^^^^^^^^^^^^^^^^^^^^^^^^^^^^^^^^^^^^^^^^^^^^^^^^^^
UnicodeDecodeError: 'utf-8' codec can't decode byte 0xd4 in position 83: invalid continuation byte
[2024-09-01T07:36:57.578+0000] {local_task_job_runner.py:261} INFO - Task exited with return code 1
[2024-09-01T07:36:57.589+0000] {warnings.py:112} WARNING - /home/***/.local/lib/python3.12/site-packages/***/models/baseoperator.py:1378: AirflowProviderDeprecationWarning: Call to deprecated class PostgresOperator. (Please use `***.providers.common.sql.operators.sql.SQLExecuteQueryOperator`.Also, you can provide `hook_params={'schema': <database>}`.)
  result = cls.__new__(cls)

[2024-09-01T07:36:57.603+0000] {taskinstance.py:3891} INFO - 0 downstream tasks scheduled from follow-on schedule check
[2024-09-01T07:36:57.608+0000] {local_task_job_runner.py:240} INFO - ::endgroup::
