[2024-08-31T19:35:32.898+0000] {local_task_job_runner.py:123} INFO - ::group::Pre task execution logs
[2024-08-31T19:35:32.919+0000] {taskinstance.py:2603} INFO - Dependencies all met for dep_context=non-requeueable deps ti=<TaskInstance: nyc_airbnb_etl.write_data manual__2024-08-31T19:35:11+00:00 [queued]>
[2024-08-31T19:35:32.929+0000] {taskinstance.py:2603} INFO - Dependencies all met for dep_context=requeueable deps ti=<TaskInstance: nyc_airbnb_etl.write_data manual__2024-08-31T19:35:11+00:00 [queued]>
[2024-08-31T19:35:32.930+0000] {taskinstance.py:2856} INFO - Starting attempt 1 of 1
[2024-08-31T19:35:32.945+0000] {taskinstance.py:2879} INFO - Executing <Task(PostgresOperator): write_data> on 2024-08-31 19:35:11+00:00
[2024-08-31T19:35:32.956+0000] {warnings.py:112} WARNING - /home/***/.local/lib/python3.12/site-packages/***/task/task_runner/standard_task_runner.py:70: DeprecationWarning: This process (pid=236) is multi-threaded, use of fork() may lead to deadlocks in the child.
  pid = os.fork()

[2024-08-31T19:35:32.958+0000] {standard_task_runner.py:72} INFO - Started process 238 to run task
[2024-08-31T19:35:32.958+0000] {standard_task_runner.py:104} INFO - Running: ['***', 'tasks', 'run', 'nyc_airbnb_etl', 'write_data', 'manual__2024-08-31T19:35:11+00:00', '--job-id', '145', '--raw', '--subdir', 'DAGS_FOLDER/nyc_airbnb_etl.py', '--cfg-path', '/tmp/tmpaoa9gesr']
[2024-08-31T19:35:32.959+0000] {standard_task_runner.py:105} INFO - Job 145: Subtask write_data
[2024-08-31T19:35:33.014+0000] {task_command.py:467} INFO - Running <TaskInstance: nyc_airbnb_etl.write_data manual__2024-08-31T19:35:11+00:00 [running]> on host f97458c89b4d
[2024-08-31T19:35:33.128+0000] {taskinstance.py:3122} INFO - Exporting env vars: AIRFLOW_CTX_DAG_OWNER='***' AIRFLOW_CTX_DAG_ID='nyc_airbnb_etl' AIRFLOW_CTX_TASK_ID='write_data' AIRFLOW_CTX_EXECUTION_DATE='2024-08-31T19:35:11+00:00' AIRFLOW_CTX_TRY_NUMBER='1' AIRFLOW_CTX_DAG_RUN_ID='manual__2024-08-31T19:35:11+00:00'
[2024-08-31T19:35:33.130+0000] {logging_mixin.py:190} INFO - Task instance is in running state
[2024-08-31T19:35:33.130+0000] {logging_mixin.py:190} INFO -  Previous state of the Task instance: queued
[2024-08-31T19:35:33.131+0000] {logging_mixin.py:190} INFO - Current task name:write_data state:running start_date:2024-08-31 19:35:32.920582+00:00
[2024-08-31T19:35:33.131+0000] {logging_mixin.py:190} INFO - Dag name:nyc_airbnb_etl and current dag run status:running
[2024-08-31T19:35:33.132+0000] {taskinstance.py:731} INFO - ::endgroup::
[2024-08-31T19:35:33.133+0000] {sql.py:282} INFO - Executing: 
            COPY your_table FROM '/opt/***/transformed/ab_nyc.csv'
            DELIMITER ','
            CSV HEADER;
        
[2024-08-31T19:35:33.150+0000] {base.py:84} INFO - Retrieving connection 'test-connection'
[2024-08-31T19:35:33.167+0000] {base.py:84} INFO - Retrieving connection 'test-connection'
[2024-08-31T19:35:33.275+0000] {taskinstance.py:3301} ERROR - Task failed with exception
Traceback (most recent call last):
  File "/home/airflow/.local/lib/python3.12/site-packages/airflow/models/taskinstance.py", line 767, in _execute_task
    result = _execute_callable(context=context, **execute_callable_kwargs)
             ^^^^^^^^^^^^^^^^^^^^^^^^^^^^^^^^^^^^^^^^^^^^^^^^^^^^^^^^^^^^^
  File "/home/airflow/.local/lib/python3.12/site-packages/airflow/models/taskinstance.py", line 733, in _execute_callable
    return ExecutionCallableRunner(
           ^^^^^^^^^^^^^^^^^^^^^^^^
  File "/home/airflow/.local/lib/python3.12/site-packages/airflow/utils/operator_helpers.py", line 252, in run
    return self.func(*args, **kwargs)
           ^^^^^^^^^^^^^^^^^^^^^^^^^^
  File "/home/airflow/.local/lib/python3.12/site-packages/airflow/models/baseoperator.py", line 406, in wrapper
    return func(self, *args, **kwargs)
           ^^^^^^^^^^^^^^^^^^^^^^^^^^^
  File "/home/airflow/.local/lib/python3.12/site-packages/airflow/providers/common/sql/operators/sql.py", line 288, in execute
    output = hook.run(
             ^^^^^^^^^
  File "/home/airflow/.local/lib/python3.12/site-packages/airflow/providers/common/sql/hooks/sql.py", line 452, in run
    with self._create_autocommit_connection(autocommit) as conn:
  File "/usr/local/lib/python3.12/contextlib.py", line 137, in __enter__
    return next(self.gen)
           ^^^^^^^^^^^^^^
  File "/home/airflow/.local/lib/python3.12/site-packages/airflow/providers/common/sql/hooks/sql.py", line 574, in _create_autocommit_connection
    with closing(self.get_conn()) as conn:
                 ^^^^^^^^^^^^^^^
  File "/home/airflow/.local/lib/python3.12/site-packages/airflow/providers/postgres/hooks/postgres.py", line 176, in get_conn
    self.conn = psycopg2.connect(**conn_args)
                ^^^^^^^^^^^^^^^^^^^^^^^^^^^^^
  File "/home/airflow/.local/lib/python3.12/site-packages/psycopg2/__init__.py", line 122, in connect
    conn = _connect(dsn, connection_factory=connection_factory, **kwasync)
           ^^^^^^^^^^^^^^^^^^^^^^^^^^^^^^^^^^^^^^^^^^^^^^^^^^^^^^^^^^^^^^^
UnicodeDecodeError: 'utf-8' codec can't decode byte 0xd4 in position 83: invalid continuation byte
[2024-08-31T19:35:33.310+0000] {logging_mixin.py:190} INFO - Task instance in failure state
[2024-08-31T19:35:33.312+0000] {logging_mixin.py:190} INFO - Task start:2024-08-31 19:35:32.920582+00:00 end:2024-08-31 19:35:33.308764+00:00 duration:0.388182
[2024-08-31T19:35:33.313+0000] {logging_mixin.py:190} INFO - Task:<Task(PostgresOperator): write_data> dag:<DAG: nyc_airbnb_etl> dagrun:<DagRun nyc_airbnb_etl @ 2024-08-31 19:35:11+00:00: manual__2024-08-31T19:35:11+00:00, state:running, queued_at: 2024-08-31 19:35:13.744965+00:00. externally triggered: True>
[2024-08-31T19:35:33.314+0000] {logging_mixin.py:190} INFO - Failure caused by 'utf-8' codec can't decode byte 0xd4 in position 83: invalid continuation byte
[2024-08-31T19:35:33.316+0000] {taskinstance.py:1225} INFO - Marking task as FAILED. dag_id=nyc_airbnb_etl, task_id=write_data, run_id=manual__2024-08-31T19:35:11+00:00, execution_date=20240831T193511, start_date=20240831T193532, end_date=20240831T193533
[2024-08-31T19:35:33.362+0000] {taskinstance.py:340} INFO - ::group::Post task execution logs
[2024-08-31T19:35:33.363+0000] {standard_task_runner.py:124} ERROR - Failed to execute job 145 for task write_data ('utf-8' codec can't decode byte 0xd4 in position 83: invalid continuation byte; 238)
Traceback (most recent call last):
  File "/home/airflow/.local/lib/python3.12/site-packages/airflow/task/task_runner/standard_task_runner.py", line 117, in _start_by_fork
    ret = args.func(args, dag=self.dag)
          ^^^^^^^^^^^^^^^^^^^^^^^^^^^^^
  File "/home/airflow/.local/lib/python3.12/site-packages/airflow/cli/cli_config.py", line 49, in command
    return func(*args, **kwargs)
           ^^^^^^^^^^^^^^^^^^^^^
  File "/home/airflow/.local/lib/python3.12/site-packages/airflow/utils/cli.py", line 115, in wrapper
    return f(*args, **kwargs)
           ^^^^^^^^^^^^^^^^^^
  File "/home/airflow/.local/lib/python3.12/site-packages/airflow/cli/commands/task_command.py", line 483, in task_run
    task_return_code = _run_task_by_selected_method(args, _dag, ti)
                       ^^^^^^^^^^^^^^^^^^^^^^^^^^^^^^^^^^^^^^^^^^^^
  File "/home/airflow/.local/lib/python3.12/site-packages/airflow/cli/commands/task_command.py", line 256, in _run_task_by_selected_method
    return _run_raw_task(args, ti)
           ^^^^^^^^^^^^^^^^^^^^^^^
  File "/home/airflow/.local/lib/python3.12/site-packages/airflow/cli/commands/task_command.py", line 341, in _run_raw_task
    return ti._run_raw_task(
           ^^^^^^^^^^^^^^^^^
  File "/home/airflow/.local/lib/python3.12/site-packages/airflow/utils/session.py", line 97, in wrapper
    return func(*args, session=session, **kwargs)
           ^^^^^^^^^^^^^^^^^^^^^^^^^^^^^^^^^^^^^^
  File "/home/airflow/.local/lib/python3.12/site-packages/airflow/models/taskinstance.py", line 2995, in _run_raw_task
    return _run_raw_task(
           ^^^^^^^^^^^^^^
  File "/home/airflow/.local/lib/python3.12/site-packages/airflow/models/taskinstance.py", line 273, in _run_raw_task
    TaskInstance._execute_task_with_callbacks(
  File "/home/airflow/.local/lib/python3.12/site-packages/airflow/models/taskinstance.py", line 3149, in _execute_task_with_callbacks
    result = self._execute_task(context, task_orig)
             ^^^^^^^^^^^^^^^^^^^^^^^^^^^^^^^^^^^^^^
  File "/home/airflow/.local/lib/python3.12/site-packages/airflow/models/taskinstance.py", line 3173, in _execute_task
    return _execute_task(self, context, task_orig)
           ^^^^^^^^^^^^^^^^^^^^^^^^^^^^^^^^^^^^^^^
  File "/home/airflow/.local/lib/python3.12/site-packages/airflow/models/taskinstance.py", line 767, in _execute_task
    result = _execute_callable(context=context, **execute_callable_kwargs)
             ^^^^^^^^^^^^^^^^^^^^^^^^^^^^^^^^^^^^^^^^^^^^^^^^^^^^^^^^^^^^^
  File "/home/airflow/.local/lib/python3.12/site-packages/airflow/models/taskinstance.py", line 733, in _execute_callable
    return ExecutionCallableRunner(
           ^^^^^^^^^^^^^^^^^^^^^^^^
  File "/home/airflow/.local/lib/python3.12/site-packages/airflow/utils/operator_helpers.py", line 252, in run
    return self.func(*args, **kwargs)
           ^^^^^^^^^^^^^^^^^^^^^^^^^^
  File "/home/airflow/.local/lib/python3.12/site-packages/airflow/models/baseoperator.py", line 406, in wrapper
    return func(self, *args, **kwargs)
           ^^^^^^^^^^^^^^^^^^^^^^^^^^^
  File "/home/airflow/.local/lib/python3.12/site-packages/airflow/providers/common/sql/operators/sql.py", line 288, in execute
    output = hook.run(
             ^^^^^^^^^
  File "/home/airflow/.local/lib/python3.12/site-packages/airflow/providers/common/sql/hooks/sql.py", line 452, in run
    with self._create_autocommit_connection(autocommit) as conn:
  File "/usr/local/lib/python3.12/contextlib.py", line 137, in __enter__
    return next(self.gen)
           ^^^^^^^^^^^^^^
  File "/home/airflow/.local/lib/python3.12/site-packages/airflow/providers/common/sql/hooks/sql.py", line 574, in _create_autocommit_connection
    with closing(self.get_conn()) as conn:
                 ^^^^^^^^^^^^^^^
  File "/home/airflow/.local/lib/python3.12/site-packages/airflow/providers/postgres/hooks/postgres.py", line 176, in get_conn
    self.conn = psycopg2.connect(**conn_args)
                ^^^^^^^^^^^^^^^^^^^^^^^^^^^^^
  File "/home/airflow/.local/lib/python3.12/site-packages/psycopg2/__init__.py", line 122, in connect
    conn = _connect(dsn, connection_factory=connection_factory, **kwasync)
           ^^^^^^^^^^^^^^^^^^^^^^^^^^^^^^^^^^^^^^^^^^^^^^^^^^^^^^^^^^^^^^^
UnicodeDecodeError: 'utf-8' codec can't decode byte 0xd4 in position 83: invalid continuation byte
[2024-08-31T19:35:33.415+0000] {local_task_job_runner.py:261} INFO - Task exited with return code 1
[2024-08-31T19:35:33.465+0000] {taskinstance.py:3891} INFO - 0 downstream tasks scheduled from follow-on schedule check
[2024-08-31T19:35:33.470+0000] {local_task_job_runner.py:240} INFO - ::endgroup::
